<<<<<<< HEAD
<robot name="robot">
=======
<robot name="manipulator">
>>>>>>> 5bb2ce3f6eb1c82aeebee7299ce19beb5bc76337

    <link name="baza">
            <visual>
                <geometry>
                    <cylinder length="1" radius="0.1"/>
                </geometry>
                <origin rpy="0 0 0" xyz="0 0 0.5"/>
                <material name="gray">
                    <color rgba="0.5 0.5 0.5 1"/>
                </material>
            </visual>
    </link>

    <link name="ramie1">
        <visual>
            <geometry>
                <box size="0.5 0.05 0.05"/>
            </geometry>
            <origin xyz="0.25 0 0.025" rpy="0 0 0"/>
            <material name="gray">
                <color rgba="0.5 0.5 0.5 1"/>
            </material>
        </visual>
    </link>

    <joint name="joint_1" type="revolute">
        <parent link="baza"/>
        <child link="ramie1"/>
        <axis xyz="0 0 1"/>
        <limit upper="3.14" lower="-3.14" effort="10" velocity="10" />
        <origin xyz="0.0 -0.0 1.0" rpy="0.0 0 0.0"/>
    </joint>

    <link name="ramie2">
        <visual>
            <geometry>
                <box size="0.5 0.05 0.05"/>
            </geometry>
            <origin xyz="0.25 0 0.025" rpy="0 0 0"/>
            <material name="gray">
                <color rgba="0.5 0.5 0.5 1"/>
            </material>
        </visual>
    </link>

    <joint name="joint_2" type="revolute">
        <parent link="ramie1"/>
        <child link="ramie2"/>
        <axis xyz="0 0 1"/>
        <limit upper="3.14" lower="-3.14" effort="10" velocity="10" />
        <origin xyz="0.5 -0.0 0.0" rpy="0.0 0 0.0"/>
    </joint>

    <link name="ramie3">
        <visual>
            <geometry>
                <box size="0.05 0.05 0.5"/>
            </geometry>
            <origin xyz="0.025 0 -0.25" rpy="0 0 0"/>
            <material name="gray">
                <color rgba="0.5 0.5 0.5 1"/>
            </material>
        </visual>
    </link>

    <joint name="joint_3" type="prismatic">
        <parent link="ramie2"/>
        <child link="ramie3"/>
        <axis xyz="0 0 1"/>
        <limit upper="5.0" lower="-5.0" effort="10" velocity="10" />
        <origin xyz="0.5 -0.0 -0.5" rpy="3.14159 0 0.0"/>
    </joint>

</robot>